2020-08-21 17:43:50,567 [django.server:154] [basehttp:log_message] [INFO]- "POST /api/add_case/ HTTP/1.1" 200 58
2020-08-21 17:44:11,358 [django.utils.autoreload:217] [autoreload:trigger_reload] [INFO]- D:\Python\auto-project\HrunManagerCloudwalk\ApiManager\views.py changed, reloading.
2020-08-21 17:44:13,297 [django.utils.autoreload:597] [autoreload:run_with_reloader] [INFO]- Watching for file changes with StatReloader
2020-08-21 17:44:18,581 [django.server:154] [basehttp:log_message] [INFO]- "POST /api/run_test/ HTTP/1.1" 200 43
2020-08-21 17:44:26,021 [django.server:154] [basehttp:log_message] [INFO]- "POST /api/add_case/ HTTP/1.1" 200 58
2020-08-21 17:44:42,189 [django.utils.autoreload:217] [autoreload:trigger_reload] [INFO]- D:\Python\auto-project\HrunManagerCloudwalk\ApiManager\views.py changed, reloading.
2020-08-21 17:44:43,207 [django.utils.autoreload:597] [autoreload:run_with_reloader] [INFO]- Watching for file changes with StatReloader
2020-08-21 17:47:56,597 [django.server:154] [basehttp:log_message] [INFO]- "POST /api/run_test/ HTTP/1.1" 200 363
2020-08-21 17:48:05,004 [django.server:154] [basehttp:log_message] [INFO]- "POST /api/add_case/ HTTP/1.1" 200 58
2020-08-21 17:48:19,498 [django.utils.autoreload:217] [autoreload:trigger_reload] [INFO]- D:\Python\auto-project\HrunManagerCloudwalk\ApiManager\views.py changed, reloading.
2020-08-21 17:48:20,575 [django.utils.autoreload:597] [autoreload:run_with_reloader] [INFO]- Watching for file changes with StatReloader
2020-08-21 17:48:25,751 [django.server:154] [basehttp:log_message] [INFO]- "POST /api/run_test/ HTTP/1.1" 200 43
2020-08-21 17:48:50,656 [django.utils.autoreload:217] [autoreload:trigger_reload] [INFO]- D:\Python\Python36\Lib\site-packages\pyflakes\api.py changed, reloading.
2020-08-21 17:48:51,949 [django.utils.autoreload:597] [autoreload:run_with_reloader] [INFO]- Watching for file changes with StatReloader
2020-08-21 17:48:57,796 [django.server:154] [basehttp:log_message] [INFO]- "POST /api/add_case/ HTTP/1.1" 200 58
2020-08-21 17:49:00,244 [django.server:154] [basehttp:log_message] [INFO]- "POST /api/run_test/ HTTP/1.1" 200 43
2020-08-21 17:49:20,745 [django.server:154] [basehttp:log_message] [INFO]- "POST /api/add_case/ HTTP/1.1" 200 58
2020-08-21 17:49:26,701 [django.server:154] [basehttp:log_message] [INFO]- "GET /api/debugtalk_list/1/ HTTP/1.1" 200 14207
2020-08-21 17:49:28,841 [django.server:154] [basehttp:log_message] [INFO]- "GET /api/debugtalk/1/ HTTP/1.1" 200 3974
2020-08-21 17:52:04,688 [django.utils.autoreload:217] [autoreload:trigger_reload] [INFO]- D:\Python\auto-project\HrunManagerCloudwalk\ApiManager\utils\runner.py changed, reloading.
2020-08-21 17:52:05,648 [django.utils.autoreload:597] [autoreload:run_with_reloader] [INFO]- Watching for file changes with StatReloader
2020-08-21 17:52:41,987 [django.server:154] [basehttp:log_message] [INFO]- "GET /api/test_list/1/ HTTP/1.1" 200 46346
2020-08-21 17:52:42,185 [django.server:154] [basehttp:log_message] [INFO]- "POST /api/add_case/ HTTP/1.1" 200 58
2020-08-21 17:52:44,985 [django.server:154] [basehttp:log_message] [INFO]- "POST /api/run_test/ HTTP/1.1" 200 251
2020-08-24 14:27:02,724 [django.server:154] [basehttp:log_message] [INFO]- "GET /api/test_list/1/ HTTP/1.1" 302 0
2020-08-24 14:27:02,731 [django.server:154] [basehttp:log_message] [INFO]- "GET /api/login/ HTTP/1.1" 200 3891
2020-08-24 14:27:04,007 [django.server:154] [basehttp:log_message] [INFO]- "POST /api/login/ HTTP/1.1" 302 0
2020-08-24 14:27:04,068 [django.server:154] [basehttp:log_message] [INFO]- "GET /api/index/ HTTP/1.1" 200 18317
2020-08-24 14:27:04,102 [django.server:154] [basehttp:log_message] [INFO]- "GET /static/assets/js/ext-language_tools.js HTTP/1.1" 304 0
2020-08-24 14:27:04,102 [django.server:154] [basehttp:log_message] [INFO]- "GET /static/assets/js/app.js HTTP/1.1" 304 0
2020-08-24 14:27:04,102 [django.server:154] [basehttp:log_message] [INFO]- "GET /static/assets/css/admin.css HTTP/1.1" 304 0
2020-08-24 14:27:04,102 [django.server:154] [basehttp:log_message] [INFO]- "GET /static/assets/css/common.css HTTP/1.1" 304 0
2020-08-24 14:27:04,104 [django.server:154] [basehttp:log_message] [INFO]- "GET /static/assets/js/commons.js HTTP/1.1" 304 0
2020-08-24 14:27:06,286 [django.server:154] [basehttp:log_message] [INFO]- "GET /api/test_list/1/ HTTP/1.1" 200 46354
2020-08-24 14:27:06,478 [django.server:154] [basehttp:log_message] [INFO]- "POST /api/add_case/ HTTP/1.1" 200 0
2020-08-24 14:27:07,683 [django.server:154] [basehttp:log_message] [INFO]- "GET /api/debugtalk_list/1/ HTTP/1.1" 200 14207
2020-08-24 14:27:09,430 [django.server:154] [basehttp:log_message] [INFO]- "GET /api/debugtalk/1/ HTTP/1.1" 200 3974
2020-08-24 14:27:14,094 [django.server:154] [basehttp:log_message] [INFO]- "GET /api/test_list/1/ HTTP/1.1" 200 46354
2020-08-24 14:27:14,268 [django.server:154] [basehttp:log_message] [INFO]- "POST /api/add_case/ HTTP/1.1" 200 0
2020-08-24 14:30:09,164 [django.server:154] [basehttp:log_message] [INFO]- "GET /api/module_list/1/ HTTP/1.1" 200 28566
2020-08-24 14:30:14,218 [django.server:154] [basehttp:log_message] [INFO]- "GET /api/test_list/1/ HTTP/1.1" 200 46354
2020-08-24 14:30:14,406 [django.server:154] [basehttp:log_message] [INFO]- "POST /api/add_case/ HTTP/1.1" 200 0
2020-08-24 14:30:50,415 [django.utils.autoreload:217] [autoreload:trigger_reload] [INFO]- D:\Python\auto-project\HrunManagerCloudwalk\ApiManager\views.py changed, reloading.
2020-08-24 14:30:51,889 [django.utils.autoreload:597] [autoreload:run_with_reloader] [INFO]- Watching for file changes with StatReloader
2020-08-24 14:31:08,690 [django.server:154] [basehttp:log_message] [INFO]- "POST /api/run_test/ HTTP/1.1" 200 251
2020-08-24 14:33:35,685 [django.utils.autoreload:217] [autoreload:trigger_reload] [INFO]- D:\Python\auto-project\HrunManagerCloudwalk\ApiManager\views.py changed, reloading.
2020-08-24 14:33:37,014 [django.utils.autoreload:597] [autoreload:run_with_reloader] [INFO]- Watching for file changes with StatReloader
2020-08-24 14:33:50,568 [django.server:154] [basehttp:log_message] [INFO]- "POST /api/add_case/ HTTP/1.1" 200 0
2020-08-24 14:33:52,530 [django.server:154] [basehttp:log_message] [INFO]- "POST /api/run_test/ HTTP/1.1" 200 251
2020-08-24 14:34:40,091 [django.utils.autoreload:217] [autoreload:trigger_reload] [INFO]- D:\Python\auto-project\HrunManagerCloudwalk\ApiManager\views.py changed, reloading.
2020-08-24 14:34:40,916 [django.utils.autoreload:597] [autoreload:run_with_reloader] [INFO]- Watching for file changes with StatReloader
2020-08-24 14:34:47,625 [django.server:154] [basehttp:log_message] [INFO]- "POST /api/add_case/ HTTP/1.1" 200 0
2020-08-24 14:34:49,665 [django.server:154] [basehttp:log_message] [INFO]- "POST /api/run_test/ HTTP/1.1" 200 251
2020-08-24 14:35:25,223 [django.utils.autoreload:217] [autoreload:trigger_reload] [INFO]- D:\Python\auto-project\HrunManagerCloudwalk\ApiManager\views.py changed, reloading.
2020-08-24 14:35:26,075 [django.utils.autoreload:597] [autoreload:run_with_reloader] [INFO]- Watching for file changes with StatReloader
2020-08-24 14:35:29,067 [django.server:154] [basehttp:log_message] [INFO]- "POST /api/add_case/ HTTP/1.1" 200 0
2020-08-24 14:35:31,073 [django.server:154] [basehttp:log_message] [INFO]- "POST /api/run_test/ HTTP/1.1" 200 251
2020-08-24 14:41:58,401 [django.server:154] [basehttp:log_message] [INFO]- "POST /api/add_case/ HTTP/1.1" 200 0
2020-08-24 14:47:58,069 [django.utils.autoreload:217] [autoreload:trigger_reload] [INFO]- D:\Python\auto-project\HrunManagerCloudwalk\ApiManager\utils\runner.py changed, reloading.
2020-08-24 14:47:59,378 [django.utils.autoreload:597] [autoreload:run_with_reloader] [INFO]- Watching for file changes with StatReloader
2020-08-24 14:54:24,661 [django.request:228] [log:log_response] [ERROR]- Internal Server Error: /api/run_test/
Traceback (most recent call last):
  File "D:\Python\auto-project\HrunManagerCloudwalk\ApiManager\views.py", line 246, in run_test
    run_test_by_type(id, base_url, testcase_dir_path, type)
  File "D:\Python\auto-project\HrunManagerCloudwalk\ApiManager\utils\runner.py", line 182, in run_test_by_type
    run_by_single(id, base_url, path)
  File "D:\Python\auto-project\HrunManagerCloudwalk\ApiManager\utils\runner.py", line 69, in run_by_single
    raise SyntaxError(error_info)
  File "<string>", line None
SyntaxError: ["D:\\Python\\auto-project\\HrunManagerCloudwalk\\suite\\like&2020-08-24-14-54-24-489\\«·÷€≤‚ ‘œÓƒø1\\debugtalk.py:19:1 undefined name 'aa'", "D:\\Python\\auto-project\\HrunManagerCloudwalk\\suite\\like&2020-08-24-14-54-24-489\\«·÷€≤‚ ‘œÓƒø1\\debugtalk.py:59:12 undefined name 'AES'", "D:\\Python\\auto-project\\HrunManagerCloudwalk\\suite\\like&2020-08-24-14-54-24-489\\«·÷€≤‚ ‘œÓƒø1\\debugtalk.py:61:15 undefined name 'AES'", "D:\\Python\\auto-project\\HrunManagerCloudwalk\\suite\\like&2020-08-24-14-54-24-489\\«·÷€≤‚ ‘œÓƒø1\\debugtalk.py:65:14 undefined name 'b2a_hex'", "D:\\Python\\auto-project\\HrunManagerCloudwalk\\suite\\like&2020-08-24-14-54-24-489\\«·÷€≤‚ ‘œÓƒø1\\debugtalk.py:77:18 undefined name 'base64'"]

During handling of the above exception, another exception occurred:

Traceback (most recent call last):
  File "D:\Python\Python36\lib\site-packages\django-2.2.12-py3.6.egg\django\core\handlers\exception.py", line 34, in inner
    response = get_response(request)
  File "D:\Python\Python36\lib\site-packages\django-2.2.12-py3.6.egg\django\core\handlers\base.py", line 115, in _get_response
    response = self.process_exception_by_middleware(e, request)
  File "D:\Python\Python36\lib\site-packages\django-2.2.12-py3.6.egg\django\core\handlers\base.py", line 113, in _get_response
    response = wrapped_callback(request, *callback_args, **callback_kwargs)
  File "D:\Python\auto-project\HrunManagerCloudwalk\HttpRunnerManager\activator.py", line 15, in process
    result = fun(request, index) if index else fun(request)
  File "D:\Python\auto-project\HrunManagerCloudwalk\ApiManager\views.py", line 40, in wrapper
    return func(request, *args, **kwargs)
  File "D:\Python\auto-project\HrunManagerCloudwalk\ApiManager\views.py", line 251, in run_test
    return render_to_response("error_info.html",{"debug_error": sy,"error_info":"debugtalk.py ”Ô∑®”–ŒÛ£¨«ÎºÏ≤ÈŒƒº˛"})
  File "D:\Python\Python36\lib\site-packages\django-2.2.12-py3.6.egg\django\shortcuts.py", line 27, in render_to_response
    content = loader.render_to_string(template_name, context, using=using)
  File "D:\Python\Python36\lib\site-packages\django-2.2.12-py3.6.egg\django\template\loader.py", line 62, in render_to_string
    return template.render(context, request)
  File "D:\Python\Python36\lib\site-packages\django-2.2.12-py3.6.egg\django\template\backends\django.py", line 61, in render
    return self.template.render(context)
  File "D:\Python\Python36\lib\site-packages\django-2.2.12-py3.6.egg\django\template\base.py", line 171, in render
    return self._render(context)
  File "D:\Python\Python36\lib\site-packages\django-2.2.12-py3.6.egg\django\template\base.py", line 163, in _render
    return self.nodelist.render(context)
  File "D:\Python\Python36\lib\site-packages\django-2.2.12-py3.6.egg\django\template\base.py", line 937, in render
    bit = node.render_annotated(context)
  File "D:\Python\Python36\lib\site-packages\django-2.2.12-py3.6.egg\django\template\base.py", line 904, in render_annotated
    return self.render(context)
  File "D:\Python\Python36\lib\site-packages\django-2.2.12-py3.6.egg\django\template\loader_tags.py", line 150, in render
    return compiled_parent._render(context)
  File "D:\Python\Python36\lib\site-packages\django-2.2.12-py3.6.egg\django\template\base.py", line 163, in _render
    return self.nodelist.render(context)
  File "D:\Python\Python36\lib\site-packages\django-2.2.12-py3.6.egg\django\template\base.py", line 937, in render
    bit = node.render_annotated(context)
  File "D:\Python\Python36\lib\site-packages\django-2.2.12-py3.6.egg\django\template\base.py", line 904, in render_annotated
    return self.render(context)
  File "D:\Python\Python36\lib\site-packages\django-2.2.12-py3.6.egg\django\template\loader_tags.py", line 62, in render
    result = block.nodelist.render(context)
  File "D:\Python\Python36\lib\site-packages\django-2.2.12-py3.6.egg\django\template\base.py", line 937, in render
    bit = node.render_annotated(context)
  File "D:\Python\Python36\lib\site-packages\django-2.2.12-py3.6.egg\django\template\base.py", line 904, in render_annotated
    return self.render(context)
  File "D:\Python\Python36\lib\site-packages\django-2.2.12-py3.6.egg\django\template\defaulttags.py", line 309, in render
    return nodelist.render(context)
  File "D:\Python\Python36\lib\site-packages\django-2.2.12-py3.6.egg\django\template\base.py", line 937, in render
    bit = node.render_annotated(context)
  File "D:\Python\Python36\lib\site-packages\django-2.2.12-py3.6.egg\django\template\base.py", line 904, in render_annotated
    return self.render(context)
  File "D:\Python\Python36\lib\site-packages\django-2.2.12-py3.6.egg\django\template\defaulttags.py", line 165, in render
    values = list(values)
TypeError: 'SyntaxError' object is not iterable
2020-08-24 14:54:24,666 [django.server:154] [basehttp:log_message] [ERROR]- "POST /api/run_test/ HTTP/1.1" 500 217941
2020-08-24 14:56:08,355 [django.utils.autoreload:217] [autoreload:trigger_reload] [INFO]- D:\Python\auto-project\HrunManagerCloudwalk\ApiManager\utils\runner.py changed, reloading.
2020-08-24 14:56:09,172 [django.utils.autoreload:597] [autoreload:run_with_reloader] [INFO]- Watching for file changes with StatReloader
2020-08-24 14:56:40,684 [django.server:154] [basehttp:log_message] [INFO]- "POST /api/add_case/ HTTP/1.1" 200 0
2020-08-24 14:56:42,666 [django.request:228] [log:log_response] [ERROR]- Internal Server Error: /api/run_test/
Traceback (most recent call last):
  File "D:\Python\auto-project\HrunManagerCloudwalk\ApiManager\views.py", line 246, in run_test
    run_test_by_type(id, base_url, testcase_dir_path, type)
  File "D:\Python\auto-project\HrunManagerCloudwalk\ApiManager\utils\runner.py", line 185, in run_test_by_type
    run_by_single(id, base_url, path)
  File "D:\Python\auto-project\HrunManagerCloudwalk\ApiManager\utils\runner.py", line 72, in run_by_single
    raise SyntaxError(err)
  File "<string>", line None
SyntaxError: D:\Python\auto-project\HrunManagerCloudwalk\suite\like&2020-08-24-14-56-42-528\«·÷€≤‚ ‘œÓƒø1\debugtalk.py:77:18 undefined name 'base64'

During handling of the above exception, another exception occurred:

Traceback (most recent call last):
  File "D:\Python\Python36\lib\site-packages\django-2.2.12-py3.6.egg\django\core\handlers\exception.py", line 34, in inner
    response = get_response(request)
  File "D:\Python\Python36\lib\site-packages\django-2.2.12-py3.6.egg\django\core\handlers\base.py", line 115, in _get_response
    response = self.process_exception_by_middleware(e, request)
  File "D:\Python\Python36\lib\site-packages\django-2.2.12-py3.6.egg\django\core\handlers\base.py", line 113, in _get_response
    response = wrapped_callback(request, *callback_args, **callback_kwargs)
  File "D:\Python\auto-project\HrunManagerCloudwalk\HttpRunnerManager\activator.py", line 15, in process
    result = fun(request, index) if index else fun(request)
  File "D:\Python\auto-project\HrunManagerCloudwalk\ApiManager\views.py", line 40, in wrapper
    return func(request, *args, **kwargs)
  File "D:\Python\auto-project\HrunManagerCloudwalk\ApiManager\views.py", line 251, in run_test
    return render_to_response("error_info.html",{"debug_error": list(sy),"error_info":"debugtalk.py ”Ô∑®”–ŒÛ£¨«ÎºÏ≤ÈŒƒº˛"})
TypeError: 'SyntaxError' object is not iterable
2020-08-24 14:56:42,670 [django.server:154] [basehttp:log_message] [ERROR]- "POST /api/run_test/ HTTP/1.1" 500 103462
2020-08-24 14:57:57,081 [django.utils.autoreload:217] [autoreload:trigger_reload] [INFO]- D:\Python\auto-project\HrunManagerCloudwalk\ApiManager\utils\runner.py changed, reloading.
2020-08-24 14:57:57,892 [django.utils.autoreload:597] [autoreload:run_with_reloader] [INFO]- Watching for file changes with StatReloader
2020-08-24 14:58:06,181 [django.server:154] [basehttp:log_message] [INFO]- "POST /api/add_case/ HTTP/1.1" 200 0
2020-08-24 14:58:08,234 [django.request:228] [log:log_response] [ERROR]- Internal Server Error: /api/run_test/
Traceback (most recent call last):
  File "D:\Python\auto-project\HrunManagerCloudwalk\ApiManager\views.py", line 246, in run_test
    run_test_by_type(id, base_url, testcase_dir_path, type)
  File "D:\Python\auto-project\HrunManagerCloudwalk\ApiManager\utils\runner.py", line 185, in run_test_by_type
    run_by_single(id, base_url, path)
  File "D:\Python\auto-project\HrunManagerCloudwalk\ApiManager\utils\runner.py", line 72, in run_by_single
    raise SyntaxError(errors)
  File "<string>", line None
SyntaxError: ["debugtalk.py:19:1 undefined name 'aa'\n", "debugtalk.py:59:12 undefined name 'AES'\n", "debugtalk.py:61:15 undefined name 'AES'\n", "debugtalk.py:65:14 undefined name 'b2a_hex'\n", "debugtalk.py:77:18 undefined name 'base64'\n"]

During handling of the above exception, another exception occurred:

Traceback (most recent call last):
  File "D:\Python\Python36\lib\site-packages\django-2.2.12-py3.6.egg\django\core\handlers\exception.py", line 34, in inner
    response = get_response(request)
  File "D:\Python\Python36\lib\site-packages\django-2.2.12-py3.6.egg\django\core\handlers\base.py", line 115, in _get_response
    response = self.process_exception_by_middleware(e, request)
  File "D:\Python\Python36\lib\site-packages\django-2.2.12-py3.6.egg\django\core\handlers\base.py", line 113, in _get_response
    response = wrapped_callback(request, *callback_args, **callback_kwargs)
  File "D:\Python\auto-project\HrunManagerCloudwalk\HttpRunnerManager\activator.py", line 15, in process
    result = fun(request, index) if index else fun(request)
  File "D:\Python\auto-project\HrunManagerCloudwalk\ApiManager\views.py", line 40, in wrapper
    return func(request, *args, **kwargs)
  File "D:\Python\auto-project\HrunManagerCloudwalk\ApiManager\views.py", line 251, in run_test
    return render_to_response("error_info.html",{"debug_error": list(sy),"error_info":"debugtalk.py ”Ô∑®”–ŒÛ£¨«ÎºÏ≤ÈŒƒº˛"})
TypeError: 'SyntaxError' object is not iterable
2020-08-24 14:58:08,238 [django.server:154] [basehttp:log_message] [ERROR]- "POST /api/run_test/ HTTP/1.1" 500 103802
2020-08-24 14:59:24,493 [django.utils.autoreload:217] [autoreload:trigger_reload] [INFO]- D:\Python\auto-project\HrunManagerCloudwalk\ApiManager\views.py changed, reloading.
2020-08-24 14:59:25,779 [django.utils.autoreload:597] [autoreload:run_with_reloader] [INFO]- Watching for file changes with StatReloader
2020-08-24 14:59:26,588 [django.server:154] [basehttp:log_message] [INFO]- "POST /api/add_case/ HTTP/1.1" 200 0
2020-08-24 14:59:31,715 [django.request:228] [log:log_response] [ERROR]- Internal Server Error: /api/run_test/
Traceback (most recent call last):
  File "D:\Python\auto-project\HrunManagerCloudwalk\ApiManager\views.py", line 246, in run_test
    run_test_by_type(id, base_url, testcase_dir_path, type)
  File "D:\Python\auto-project\HrunManagerCloudwalk\ApiManager\utils\runner.py", line 185, in run_test_by_type
    run_by_single(id, base_url, path)
  File "D:\Python\auto-project\HrunManagerCloudwalk\ApiManager\utils\runner.py", line 72, in run_by_single
    raise SyntaxError(errors)
  File "<string>", line None
SyntaxError: ["debugtalk.py:19:1 undefined name 'aa'\n", "debugtalk.py:59:12 undefined name 'AES'\n", "debugtalk.py:61:15 undefined name 'AES'\n", "debugtalk.py:65:14 undefined name 'b2a_hex'\n", "debugtalk.py:77:18 undefined name 'base64'\n"]

During handling of the above exception, another exception occurred:

Traceback (most recent call last):
  File "D:\Python\Python36\lib\site-packages\django-2.2.12-py3.6.egg\django\core\handlers\exception.py", line 34, in inner
    response = get_response(request)
  File "D:\Python\Python36\lib\site-packages\django-2.2.12-py3.6.egg\django\core\handlers\base.py", line 115, in _get_response
    response = self.process_exception_by_middleware(e, request)
  File "D:\Python\Python36\lib\site-packages\django-2.2.12-py3.6.egg\django\core\handlers\base.py", line 113, in _get_response
    response = wrapped_callback(request, *callback_args, **callback_kwargs)
  File "D:\Python\auto-project\HrunManagerCloudwalk\HttpRunnerManager\activator.py", line 15, in process
    result = fun(request, index) if index else fun(request)
  File "D:\Python\auto-project\HrunManagerCloudwalk\ApiManager\views.py", line 40, in wrapper
    return func(request, *args, **kwargs)
  File "D:\Python\auto-project\HrunManagerCloudwalk\ApiManager\views.py", line 250, in run_test
    logger.info("SyntaxErrorµƒ±®¥Ì–≈œ¢ «£∫{}£¨\n ∑µªÿ÷µµƒtype «£∫{}".format(sy,type(sy)))
TypeError: 'str' object is not callable
2020-08-24 14:59:31,719 [django.server:154] [basehttp:log_message] [ERROR]- "POST /api/run_test/ HTTP/1.1" 500 103953
2020-08-24 15:00:15,416 [django.utils.autoreload:217] [autoreload:trigger_reload] [INFO]- D:\Python\auto-project\HrunManagerCloudwalk\ApiManager\views.py changed, reloading.
2020-08-24 15:00:16,237 [django.utils.autoreload:597] [autoreload:run_with_reloader] [INFO]- Watching for file changes with StatReloader
2020-08-24 15:00:22,883 [django.server:154] [basehttp:log_message] [INFO]- "POST /api/add_case/ HTTP/1.1" 200 0
2020-08-24 15:00:24,513 [django.request:228] [log:log_response] [ERROR]- Internal Server Error: /api/run_test/
Traceback (most recent call last):
  File "D:\Python\auto-project\HrunManagerCloudwalk\ApiManager\views.py", line 246, in run_test
    run_test_by_type(id, base_url, testcase_dir_path, type_request)
  File "D:\Python\auto-project\HrunManagerCloudwalk\ApiManager\utils\runner.py", line 185, in run_test_by_type
    run_by_single(id, base_url, path)
  File "D:\Python\auto-project\HrunManagerCloudwalk\ApiManager\utils\runner.py", line 72, in run_by_single
    raise SyntaxError(errors)
  File "<string>", line None
SyntaxError: ["debugtalk.py:19:1 undefined name 'aa'\n", "debugtalk.py:59:12 undefined name 'AES'\n", "debugtalk.py:61:15 undefined name 'AES'\n", "debugtalk.py:65:14 undefined name 'b2a_hex'\n", "debugtalk.py:77:18 undefined name 'base64'\n"]

During handling of the above exception, another exception occurred:

Traceback (most recent call last):
  File "D:\Python\Python36\lib\site-packages\django-2.2.12-py3.6.egg\django\core\handlers\exception.py", line 34, in inner
    response = get_response(request)
  File "D:\Python\Python36\lib\site-packages\django-2.2.12-py3.6.egg\django\core\handlers\base.py", line 115, in _get_response
    response = self.process_exception_by_middleware(e, request)
  File "D:\Python\Python36\lib\site-packages\django-2.2.12-py3.6.egg\django\core\handlers\base.py", line 113, in _get_response
    response = wrapped_callback(request, *callback_args, **callback_kwargs)
  File "D:\Python\auto-project\HrunManagerCloudwalk\HttpRunnerManager\activator.py", line 15, in process
    result = fun(request, index) if index else fun(request)
  File "D:\Python\auto-project\HrunManagerCloudwalk\ApiManager\views.py", line 40, in wrapper
    return func(request, *args, **kwargs)
  File "D:\Python\auto-project\HrunManagerCloudwalk\ApiManager\views.py", line 250, in run_test
    logger.info("SyntaxErrorµƒ±®¥Ì–≈œ¢ «£∫{}£¨\n ∑µªÿ÷µµƒtype «£∫{}".format(sy,type(sy)))
UnboundLocalError: local variable 'type' referenced before assignment
2020-08-24 15:00:24,516 [django.server:154] [basehttp:log_message] [ERROR]- "POST /api/run_test/ HTTP/1.1" 500 104145
2020-08-24 15:00:48,722 [django.utils.autoreload:217] [autoreload:trigger_reload] [INFO]- D:\Python\auto-project\HrunManagerCloudwalk\ApiManager\views.py changed, reloading.
2020-08-24 15:00:49,551 [django.utils.autoreload:597] [autoreload:run_with_reloader] [INFO]- Watching for file changes with StatReloader
2020-08-24 15:00:52,617 [django.server:154] [basehttp:log_message] [INFO]- "POST /api/add_case/ HTTP/1.1" 200 0
2020-08-24 15:00:54,570 [django.request:228] [log:log_response] [ERROR]- Internal Server Error: /api/run_test/
Traceback (most recent call last):
  File "D:\Python\auto-project\HrunManagerCloudwalk\ApiManager\views.py", line 246, in run_test
    run_test_by_type(id, base_url, testcase_dir_path, type_request)
  File "D:\Python\auto-project\HrunManagerCloudwalk\ApiManager\utils\runner.py", line 185, in run_test_by_type
    run_by_single(id, base_url, path)
  File "D:\Python\auto-project\HrunManagerCloudwalk\ApiManager\utils\runner.py", line 72, in run_by_single
    raise SyntaxError(errors)
  File "<string>", line None
SyntaxError: ["debugtalk.py:19:1 undefined name 'aa'\n", "debugtalk.py:59:12 undefined name 'AES'\n", "debugtalk.py:61:15 undefined name 'AES'\n", "debugtalk.py:65:14 undefined name 'b2a_hex'\n", "debugtalk.py:77:18 undefined name 'base64'\n"]

During handling of the above exception, another exception occurred:

Traceback (most recent call last):
  File "D:\Python\Python36\lib\site-packages\django-2.2.12-py3.6.egg\django\core\handlers\exception.py", line 34, in inner
    response = get_response(request)
  File "D:\Python\Python36\lib\site-packages\django-2.2.12-py3.6.egg\django\core\handlers\base.py", line 115, in _get_response
    response = self.process_exception_by_middleware(e, request)
  File "D:\Python\Python36\lib\site-packages\django-2.2.12-py3.6.egg\django\core\handlers\base.py", line 113, in _get_response
    response = wrapped_callback(request, *callback_args, **callback_kwargs)
  File "D:\Python\auto-project\HrunManagerCloudwalk\HttpRunnerManager\activator.py", line 15, in process
    result = fun(request, index) if index else fun(request)
  File "D:\Python\auto-project\HrunManagerCloudwalk\ApiManager\views.py", line 40, in wrapper
    return func(request, *args, **kwargs)
  File "D:\Python\auto-project\HrunManagerCloudwalk\ApiManager\views.py", line 251, in run_test
    return render_to_response("error_info.html",{"debug_error": list(sy),"error_info":"debugtalk.py ”Ô∑®”–ŒÛ£¨«ÎºÏ≤ÈŒƒº˛"})
TypeError: 'SyntaxError' object is not iterable
2020-08-24 15:00:54,573 [django.server:154] [basehttp:log_message] [ERROR]- "POST /api/run_test/ HTTP/1.1" 500 104046
2020-08-24 15:01:22,324 [django.utils.autoreload:217] [autoreload:trigger_reload] [INFO]- D:\Python\auto-project\HrunManagerCloudwalk\ApiManager\views.py changed, reloading.
2020-08-24 15:01:23,391 [django.utils.autoreload:597] [autoreload:run_with_reloader] [INFO]- Watching for file changes with StatReloader
2020-08-24 15:01:24,078 [django.server:154] [basehttp:log_message] [INFO]- "POST /api/add_case/ HTTP/1.1" 200 0
2020-08-24 15:01:25,840 [django.request:228] [log:log_response] [ERROR]- Internal Server Error: /api/run_test/
Traceback (most recent call last):
  File "D:\Python\auto-project\HrunManagerCloudwalk\ApiManager\views.py", line 246, in run_test
    run_test_by_type(id, base_url, testcase_dir_path, type_request)
  File "D:\Python\auto-project\HrunManagerCloudwalk\ApiManager\utils\runner.py", line 185, in run_test_by_type
    run_by_single(id, base_url, path)
  File "D:\Python\auto-project\HrunManagerCloudwalk\ApiManager\utils\runner.py", line 72, in run_by_single
    raise SyntaxError(errors)
  File "<string>", line None
SyntaxError: ["debugtalk.py:19:1 undefined name 'aa'\n", "debugtalk.py:59:12 undefined name 'AES'\n", "debugtalk.py:61:15 undefined name 'AES'\n", "debugtalk.py:65:14 undefined name 'b2a_hex'\n", "debugtalk.py:77:18 undefined name 'base64'\n"]

During handling of the above exception, another exception occurred:

Traceback (most recent call last):
  File "D:\Python\Python36\lib\site-packages\django-2.2.12-py3.6.egg\django\core\handlers\exception.py", line 34, in inner
    response = get_response(request)
  File "D:\Python\Python36\lib\site-packages\django-2.2.12-py3.6.egg\django\core\handlers\base.py", line 115, in _get_response
    response = self.process_exception_by_middleware(e, request)
  File "D:\Python\Python36\lib\site-packages\django-2.2.12-py3.6.egg\django\core\handlers\base.py", line 113, in _get_response
    response = wrapped_callback(request, *callback_args, **callback_kwargs)
  File "D:\Python\auto-project\HrunManagerCloudwalk\HttpRunnerManager\activator.py", line 15, in process
    result = fun(request, index) if index else fun(request)
  File "D:\Python\auto-project\HrunManagerCloudwalk\ApiManager\views.py", line 40, in wrapper
    return func(request, *args, **kwargs)
  File "D:\Python\auto-project\HrunManagerCloudwalk\ApiManager\views.py", line 250, in run_test
    logger.info("SyntaxErrorµƒ±®¥Ì–≈œ¢ «£∫{}£¨\n ∑µªÿ÷µµƒtype «£∫{}".format(sy,type(eval(sy))))
TypeError: eval() arg 1 must be a string, bytes or code object
2020-08-24 15:01:25,843 [django.server:154] [basehttp:log_message] [ERROR]- "POST /api/run_test/ HTTP/1.1" 500 104085
2020-08-24 15:01:59,081 [django.utils.autoreload:217] [autoreload:trigger_reload] [INFO]- D:\Python\auto-project\HrunManagerCloudwalk\ApiManager\views.py changed, reloading.
2020-08-24 15:01:59,896 [django.utils.autoreload:597] [autoreload:run_with_reloader] [INFO]- Watching for file changes with StatReloader
2020-08-24 15:02:02,858 [django.server:154] [basehttp:log_message] [INFO]- "POST /api/add_case/ HTTP/1.1" 200 0
2020-08-24 15:02:04,413 [django.request:228] [log:log_response] [ERROR]- Internal Server Error: /api/run_test/
Traceback (most recent call last):
  File "D:\Python\auto-project\HrunManagerCloudwalk\ApiManager\views.py", line 246, in run_test
    run_test_by_type(id, base_url, testcase_dir_path, type_request)
  File "D:\Python\auto-project\HrunManagerCloudwalk\ApiManager\utils\runner.py", line 185, in run_test_by_type
    run_by_single(id, base_url, path)
  File "D:\Python\auto-project\HrunManagerCloudwalk\ApiManager\utils\runner.py", line 72, in run_by_single
    raise SyntaxError(errors)
  File "<string>", line None
SyntaxError: ["debugtalk.py:19:1 undefined name 'aa'\n", "debugtalk.py:59:12 undefined name 'AES'\n", "debugtalk.py:61:15 undefined name 'AES'\n", "debugtalk.py:65:14 undefined name 'b2a_hex'\n", "debugtalk.py:77:18 undefined name 'base64'\n"]

During handling of the above exception, another exception occurred:

Traceback (most recent call last):
  File "D:\Python\Python36\lib\site-packages\django-2.2.12-py3.6.egg\django\core\handlers\exception.py", line 34, in inner
    response = get_response(request)
  File "D:\Python\Python36\lib\site-packages\django-2.2.12-py3.6.egg\django\core\handlers\base.py", line 115, in _get_response
    response = self.process_exception_by_middleware(e, request)
  File "D:\Python\Python36\lib\site-packages\django-2.2.12-py3.6.egg\django\core\handlers\base.py", line 113, in _get_response
    response = wrapped_callback(request, *callback_args, **callback_kwargs)
  File "D:\Python\auto-project\HrunManagerCloudwalk\HttpRunnerManager\activator.py", line 15, in process
    result = fun(request, index) if index else fun(request)
  File "D:\Python\auto-project\HrunManagerCloudwalk\ApiManager\views.py", line 40, in wrapper
    return func(request, *args, **kwargs)
  File "D:\Python\auto-project\HrunManagerCloudwalk\ApiManager\views.py", line 251, in run_test
    return render_to_response("error_info.html",{"debug_error": list(sy),"error_info":"debugtalk.py ”Ô∑®”–ŒÛ£¨«ÎºÏ≤ÈŒƒº˛"})
TypeError: 'SyntaxError' object is not iterable
2020-08-24 15:02:04,416 [django.server:154] [basehttp:log_message] [ERROR]- "POST /api/run_test/ HTTP/1.1" 500 104068
2020-08-24 15:02:18,964 [django.utils.autoreload:217] [autoreload:trigger_reload] [INFO]- D:\Python\auto-project\HrunManagerCloudwalk\ApiManager\views.py changed, reloading.
2020-08-24 15:02:20,140 [django.utils.autoreload:597] [autoreload:run_with_reloader] [INFO]- Watching for file changes with StatReloader
2020-08-24 15:02:23,051 [django.server:154] [basehttp:log_message] [INFO]- "POST /api/add_case/ HTTP/1.1" 200 0
2020-08-24 15:02:24,901 [django.server:154] [basehttp:log_message] [INFO]- "POST /api/run_test/ HTTP/1.1" 200 13119
2020-08-24 15:04:43,662 [django.server:154] [basehttp:log_message] [INFO]- "POST /api/add_case/ HTTP/1.1" 200 0
2020-08-24 15:04:45,565 [django.server:154] [basehttp:log_message] [INFO]- "POST /api/run_test/ HTTP/1.1" 200 13044
2020-08-24 15:05:58,981 [django.server:154] [basehttp:log_message] [INFO]- "GET /api/test_list/1/ HTTP/1.1" 200 46354
2020-08-24 15:05:59,237 [django.server:154] [basehttp:log_message] [INFO]- "POST /api/add_case/ HTTP/1.1" 200 0
2020-08-24 15:07:23,790 [django.server:154] [basehttp:log_message] [INFO]- "GET /api/test_list/1/ HTTP/1.1" 200 46354
2020-08-24 15:07:24,079 [django.server:154] [basehttp:log_message] [INFO]- "POST /api/add_case/ HTTP/1.1" 200 0
2020-08-24 15:07:56,802 [django.server:154] [basehttp:log_message] [INFO]- "POST /api/run_test/ HTTP/1.1" 200 13043
2020-08-24 15:09:38,303 [django.server:154] [basehttp:log_message] [INFO]- "GET /api/test_list/1/ HTTP/1.1" 200 46354
2020-08-24 15:09:38,624 [django.server:154] [basehttp:log_message] [INFO]- "POST /api/add_case/ HTTP/1.1" 200 0
2020-08-24 15:09:43,168 [django.server:154] [basehttp:log_message] [INFO]- "GET /api/add_case/ HTTP/1.1" 200 36565
2020-08-24 15:12:39,734 [django.server:154] [basehttp:log_message] [INFO]- "GET /api/config_list/1/ HTTP/1.1" 200 24678
2020-08-24 15:12:39,888 [django.server:154] [basehttp:log_message] [INFO]- "POST /api/add_case/ HTTP/1.1" 200 0
2020-08-24 15:14:56,495 [django.server:154] [basehttp:log_message] [INFO]- "GET /api/test_list/1/ HTTP/1.1" 200 46354
2020-08-24 15:14:56,687 [django.server:154] [basehttp:log_message] [INFO]- "POST /api/add_case/ HTTP/1.1" 200 0
2020-08-24 15:14:59,315 [django.request:228] [log:log_response] [ERROR]- Internal Server Error: /api/run_test/
Traceback (most recent call last):
  File "D:\Python\auto-project\HrunManagerCloudwalk\ApiManager\views.py", line 246, in run_test
    run_test_by_type(id, base_url, testcase_dir_path, type_request)
  File "D:\Python\auto-project\HrunManagerCloudwalk\ApiManager\utils\runner.py", line 185, in run_test_by_type
    run_by_single(id, base_url, path)
  File "D:\Python\auto-project\HrunManagerCloudwalk\ApiManager\utils\runner.py", line 72, in run_by_single
    raise SyntaxError(errors)
  File "<string>", line None
SyntaxError: ["debugtalk.py:19:1 undefined name 'aa'\n", "debugtalk.py:59:12 undefined name 'AES'\n", "debugtalk.py:61:15 undefined name 'AES'\n", "debugtalk.py:65:14 undefined name 'b2a_hex'\n", "debugtalk.py:77:18 undefined name 'base64'\n"]

During handling of the above exception, another exception occurred:

Traceback (most recent call last):
  File "D:\Python\Python36\lib\site-packages\django-2.2.12-py3.6.egg\django\template\base.py", line 470, in parse
    compile_func = self.tags[command]
KeyError: 'endblock'

During handling of the above exception, another exception occurred:

Traceback (most recent call last):
  File "D:\Python\Python36\lib\site-packages\django-2.2.12-py3.6.egg\django\core\handlers\exception.py", line 34, in inner
    response = get_response(request)
  File "D:\Python\Python36\lib\site-packages\django-2.2.12-py3.6.egg\django\core\handlers\base.py", line 115, in _get_response
    response = self.process_exception_by_middleware(e, request)
  File "D:\Python\Python36\lib\site-packages\django-2.2.12-py3.6.egg\django\core\handlers\base.py", line 113, in _get_response
    response = wrapped_callback(request, *callback_args, **callback_kwargs)
  File "D:\Python\auto-project\HrunManagerCloudwalk\HttpRunnerManager\activator.py", line 15, in process
    result = fun(request, index) if index else fun(request)
  File "D:\Python\auto-project\HrunManagerCloudwalk\ApiManager\views.py", line 40, in wrapper
    return func(request, *args, **kwargs)
  File "D:\Python\auto-project\HrunManagerCloudwalk\ApiManager\views.py", line 251, in run_test
    return render_to_response("error_info.html",{"debug_error": eval(str(sy)),"error_info":"debugtalk.py ”Ô∑®”–ŒÛ£¨«ÎºÏ≤ÈŒƒº˛"})
  File "D:\Python\Python36\lib\site-packages\django-2.2.12-py3.6.egg\django\shortcuts.py", line 27, in render_to_response
    content = loader.render_to_string(template_name, context, using=using)
  File "D:\Python\Python36\lib\site-packages\django-2.2.12-py3.6.egg\django\template\loader.py", line 61, in render_to_string
    template = get_template(template_name, using=using)
  File "D:\Python\Python36\lib\site-packages\django-2.2.12-py3.6.egg\django\template\loader.py", line 15, in get_template
    return engine.get_template(template_name)
  File "D:\Python\Python36\lib\site-packages\django-2.2.12-py3.6.egg\django\template\backends\django.py", line 34, in get_template
    return Template(self.engine.get_template(template_name), self)
  File "D:\Python\Python36\lib\site-packages\django-2.2.12-py3.6.egg\django\template\engine.py", line 143, in get_template
    template, origin = self.find_template(template_name)
  File "D:\Python\Python36\lib\site-packages\django-2.2.12-py3.6.egg\django\template\engine.py", line 125, in find_template
    template = loader.get_template(name, skip=skip)
  File "D:\Python\Python36\lib\site-packages\django-2.2.12-py3.6.egg\django\template\loaders\base.py", line 30, in get_template
    contents, origin, origin.template_name, self.engine,
  File "D:\Python\Python36\lib\site-packages\django-2.2.12-py3.6.egg\django\template\base.py", line 156, in __init__
    self.nodelist = self.compile_nodelist()
  File "D:\Python\Python36\lib\site-packages\django-2.2.12-py3.6.egg\django\template\base.py", line 194, in compile_nodelist
    return parser.parse()
  File "D:\Python\Python36\lib\site-packages\django-2.2.12-py3.6.egg\django\template\base.py", line 478, in parse
    raise self.error(token, e)
  File "D:\Python\Python36\lib\site-packages\django-2.2.12-py3.6.egg\django\template\base.py", line 476, in parse
    compiled_result = compile_func(self, token)
  File "D:\Python\Python36\lib\site-packages\django-2.2.12-py3.6.egg\django\template\loader_tags.py", line 266, in do_extends
    nodelist = parser.parse()
  File "D:\Python\Python36\lib\site-packages\django-2.2.12-py3.6.egg\django\template\base.py", line 472, in parse
    self.invalid_block_tag(token, command, parse_until)
  File "D:\Python\Python36\lib\site-packages\django-2.2.12-py3.6.egg\django\template\base.py", line 534, in invalid_block_tag
    "or load this tag?" % (token.lineno, command)
django.template.exceptions.TemplateSyntaxError: Invalid block tag on line 36: 'endblock'. Did you forget to register or load this tag?
2020-08-24 15:14:59,321 [django.server:154] [basehttp:log_message] [ERROR]- "POST /api/run_test/ HTTP/1.1" 500 178927
2020-08-24 16:07:25,747 [django.server:154] [basehttp:log_message] [INFO]- "POST /api/add_case/ HTTP/1.1" 302 0
2020-08-24 16:07:25,759 [django.server:154] [basehttp:log_message] [INFO]- "GET /api/login/ HTTP/1.1" 200 3891
2020-08-24 16:12:30,501 [django.server:154] [basehttp:log_message] [INFO]- "POST /api/run_test/ HTTP/1.1" 302 0
2020-08-24 16:12:30,504 [django.server:154] [basehttp:log_message] [INFO]- "GET /api/login/ HTTP/1.1" 200 3891
2020-08-24 16:12:30,518 [django.server:154] [basehttp:log_message] [INFO]- "GET /static/assets/iconfont/style.css HTTP/1.1" 304 0
2020-08-24 16:12:30,519 [django.server:154] [basehttp:log_message] [INFO]- "GET /static/assets/img/bg.jpg HTTP/1.1" 304 0
2020-08-24 16:12:30,520 [django.server:154] [basehttp:log_message] [INFO]- "GET /static/assets/img/main_bg.png HTTP/1.1" 304 0
2020-08-24 16:12:30,536 [django.server:154] [basehttp:log_message] [INFO]- "GET /static/assets/iconfont/fonts/icomoon.ttf?u4m6fy HTTP/1.1" 304 0
2020-08-24 16:12:31,748 [django.server:154] [basehttp:log_message] [INFO]- "POST /api/login/ HTTP/1.1" 302 0
2020-08-24 16:12:31,805 [django.server:154] [basehttp:log_message] [INFO]- "GET /api/index/ HTTP/1.1" 200 18317
2020-08-24 16:12:34,955 [django.server:154] [basehttp:log_message] [INFO]- "GET /api/test_list/1/ HTTP/1.1" 200 46354
2020-08-24 16:12:35,159 [django.server:154] [basehttp:log_message] [INFO]- "POST /api/add_case/ HTTP/1.1" 200 0
2020-08-24 16:12:41,129 [django.server:154] [basehttp:log_message] [INFO]- "POST /api/run_test/ HTTP/1.1" 200 13439
2020-08-24 16:13:07,914 [django.server:154] [basehttp:log_message] [INFO]- "POST /api/add_case/ HTTP/1.1" 200 0
2020-08-24 16:13:09,960 [django.server:154] [basehttp:log_message] [INFO]- "POST /api/run_test/ HTTP/1.1" 200 13389
2020-08-24 16:13:28,662 [django.server:154] [basehttp:log_message] [INFO]- "POST /api/add_case/ HTTP/1.1" 200 0
2020-08-24 16:13:30,896 [django.server:154] [basehttp:log_message] [INFO]- "POST /api/run_test/ HTTP/1.1" 200 13386
2020-08-24 16:14:05,224 [django.server:154] [basehttp:log_message] [INFO]- "POST /api/add_case/ HTTP/1.1" 200 0
2020-08-24 16:14:07,004 [django.server:154] [basehttp:log_message] [INFO]- "POST /api/run_test/ HTTP/1.1" 200 13143
2020-08-24 16:14:32,042 [django.server:154] [basehttp:log_message] [INFO]- "POST /api/add_case/ HTTP/1.1" 200 0
2020-08-24 16:14:33,675 [django.server:154] [basehttp:log_message] [INFO]- "POST /api/run_test/ HTTP/1.1" 200 12949
2020-08-24 16:15:13,472 [django.server:154] [basehttp:log_message] [INFO]- "POST /api/add_case/ HTTP/1.1" 200 0
2020-08-24 16:15:16,087 [django.server:154] [basehttp:log_message] [INFO]- "POST /api/run_test/ HTTP/1.1" 200 12949
2020-08-24 16:16:16,801 [django.server:154] [basehttp:log_message] [INFO]- "POST /api/add_case/ HTTP/1.1" 200 0
2020-08-24 16:16:47,217 [django.utils.autoreload:217] [autoreload:trigger_reload] [INFO]- D:\Python\auto-project\HrunManagerCloudwalk\ApiManager\views.py changed, reloading.
2020-08-24 16:16:48,039 [django.utils.autoreload:597] [autoreload:run_with_reloader] [INFO]- Watching for file changes with StatReloader
